Workbook
Name Price_Total: MIF!$P$3

Sheet Nomenclature
B1: Seri | C1: Model | D1: Yön | E1: Besleme Filtre | F1: Dönüş Filtre | G1: Soğutucu Batarya | H1: Dış Ortam | I1: Ön Isıtıcı | J1: TCP/IP
B2: HPL | C2: 7 | D2: R | E2: 7 | F2: 5 | G2: 0 | H2: 0 | I2: 0 | J2: 0
C3: 11 | D3: L | E3: 5 | F3: 5 | G3: C | H3: 1 | I3: 1 | J3: 1
C4: 15 | E4: 47 | F4: 5
C5: 22 | E5: 49 | F5: 5
C6: 32
C7: 42
C8: 53
C9: 64
C10: 90
C11: cmbDeviceFlow | D11: cmbDirection | E11: cmbSupplyFilter | F11: cmbReturnFilter | G11: Eğer HPL 22...90 modeli seçilmiş, Sıcaklık 30 °C ve mutlak nem 14,3 g/kg değerinin üzerinde ise = 1 olacak. Diğer durumlarda "0" dır. | H11: cmbOutDoor | I11: Eğer HPL 22...90 modeli seçilmiş, Taze Hava giriş sıcaklığı -6 ve altı ise = 1 olacaktır. Diğer durumlarda "0" olacaktır. | J11: cmbBMS

Sheet MIF
B1: Model | C1: Yön | D1: Besleme Filtre | E1: Dönüş Filtre | F1: Soğutucu Batarya | G1: Dış Ortam | H1: Ön Isıtıcı | I1: TCP/IP
B2: 7 | C2: R | D2: 7 | E2: 5 | F2: 0 | G2: 0 | H2: 0 | I2: 0
N3: CİHAZ TOPLAM FİYAT: | P3: =SUM(P7:P167) -> 6044.2708
I5: MALZEME LİSTESİ
I6: Sınıf | J6: No | K6: MALZEME ADI | L6: ERP KODU | M6: BİRİM | N6: MİKTAR | O6: BİRİM FİYAT | P6: TOPLAM FİYAT
I7: {=_xlfn.LET( _xlpm.S_Adi, B2, _xlpm.Urunler, INDIRECT("'"&_xlpm.S_Adi&"'!L3:S250"), _xlpm.G_Kontrol, INDIRECT("'"&_xlpm.S_Adi&"'!J3:J250"), _xlpm.C_Krit, (INDIRECT("'"&_xlpm.S_Adi&"'!C3:C250")=C2) + (INDIRECT("'"&_xlpm.S_Adi&"'!C3:C250")="sabit"), _xlpm.D_Krit, (INDIRECT("'"&_xlpm.S_Adi&"'!D3:D250")=D2) + (INDIRECT("'"&_xlpm.S_Adi&"'!D3:D250")="sabit"), _xlpm.E_Krit, (INDIRECT("'"&_xlpm.S_Adi&"'!E3:E250")=E2) + (INDIRECT("'"&_xlpm.S_Adi&"'!E3:E250")="sabit"), _xlpm.F_Krit, (INDIRECT("'"&_xlpm.S_Adi&"'!F3:F250")=F2) + (INDIRECT("'"&_xlpm.S_Adi&"'!F3:F250")="sabit"), _xlpm.G_Krit, (INDIRECT("'"&_xlpm.S_Adi&"'!G3:G250")=G2) + (INDIRECT("'"&_xlpm.S_Adi&"'!G3:G250")="sabit"), _xlpm.H_Krit, (INDIRECT("'"&_xlpm.S_Adi&"'!H3:H250")=H2) + (INDIRECT("'"&_xlpm.S_Adi&"'!H3:H250")="sabit"), _xlpm.I_Krit, (INDIRECT("'"&_xlpm.S_Adi&"'!I3:I250")=I2) + (INDIRECT("'"&_xlpm.S_Adi&"'!I3:I250")="sabit"), _xlpm.Sonuc, _xlfn._xlws.FILTER(_xlpm.Urunler, (_xlpm.C_Krit * _xlpm.D_Krit * _xlpm.E_Krit * _xlpm.F_Krit * _xlpm.G_Krit * _xlpm.H_Krit * _xlpm.I_Krit * (_xlpm.G_Kontrol=1)), ""), _xlfn.UNIQUE(_xlpm.Sonuc) )} -> MEKANİK | J7: 1 | K7: Kompresör ZP36K5E-TFD | L7: R20KMZP036K5E | M7: Adet | N7: 1 | O7: 1 | P7: 1
I8: MEKANİK | J8: 2 | K8: Copeland Karter Isıtıcı ID:8561150 | L8: R20KI08561150 | M8: Adet | N8: 1 | O8: 39.921 | P8: 39.921
I9: MEKANİK | J9: 3 | K9: 4 Yollu Vana SHF-14A-46 1/2"x3/4" | L9: R20V144612340 | M9: Adet | N9: 1 | O9: 60 | P9: 60
I10: MEKANİK | J10: 4 | K10: 4 Yollu Vana Bobini 220V AC 4,5W Kablolu | L10: R27SVB2204500 | M10: Adet | N10: 1 | O10: 12.8 | P10: 12.8
I11: MEKANİK | J11: 5 | K11: Danfoss NRV 10 s 02B1011 3/8" Check Valve | L11: R20NRV10S3801 | M11: Adet | N11: 4 | O11: 13.05 | P11: 52.2
I12: MEKANİK | J12: 6 | K12: Danfoss Drier DML083 3/8" 023Z5040 | L12: R20DML0833801 | M12: Adet | N12: 1 | O12: 10.15 | P12: 10.15
I13: MEKANİK | J13: 7 | K13: Danfoss Gözetleme Camı Kaynaklı SGP 10s N 3/8" 014L0182 | L13: R20SGP10SN380 | M13: Adet | N13: 1 | O13: 9.5 | P13: 9.5
I14: MEKANİK | J14: 8 | K14: Danfoss Küresel Vana GBC 10s 3/8" 009L7021 | L14: R20GBC1038702 | M14: Adet | N14: 1 | O14: 18 | P14: 18
I15: MEKANİK | J15: 9 | K15: GVN LİKİT TANKI VLR.A.33b.02.B2.C2 | L15: R20LTVLR02221 | M15: Adet | N15: 1 | O15: 0 | P15: 0
I16: MEKANİK | J16: 10 | K16: GVN EMİŞ AKÜMÜLATÖRÜ SLA.33B.19.1.7 | L16: R20SLA1917000 | M16: Adet | N16: 1 | O16: 0 | P16: 0
I17: MEKANİK | J17: 11 | K17: BAKIR BORU Q19 (3/4")-1 MM | L17: R20BBQ1900000 | M17: Adet | N17: 4 | O17: 9.65 | P17: 38.6
I18: MEKANİK | J18: 12 | K18: BAKIR BORU Q9,52 (3/8")-1 MM | L18: R20BBQ9520000 | M18: Adet | N18: 3.5 | O18: 4.65 | P18: 16.275
I19: MEKANİK | J19: 13 | K19: BAKIR TE 3/8"-3/8"-3/8" | L19: R20BT00383838 | M19: Adet | N19: 2 | O19: 0.4 | P19: 0.8
... I90: OTOMASYON | J90: 84 | K90: LIHCH KABLO 2X0,75 | L90: R12KBLIHCH2X0 | M90: Metre | N90: 45 | O90: 0 | P90: 0

Sheet Malzemeler
A2: Model | B2: Malzeme adı | C2: Kodu
A3: HPL 7 | B3: Kompresör ZP36K5E-TFD | C3: R20KMZP036K5E | D3: 1 | E3: 482.22
A4: HPL 11 | B4: Kompresör ZP61 K5E TFD 522 | C4: R20KMZP61K001 | D4: 629.96
A5: HPL 15 | B5: Kompresör ZP91KCE-TFD 3/4x7/8 | C5: R20KMZP053400 | D5: 906.12
A6: HPL 22 | B6: Kompresör ZP104 KCE TFD 455 | C6: R20KMZP104001 | D6: 1211.04
A7: HPL 32 | B7: Kompresör ZP122KCE-TFD 7/8x11/8 | C7: R20KMZP122003 | D7: 1444.06
A8: HPL 42 | B8: Kompresör ZP182KCE-TFD 7/8x13/8 | C8: R20KMZP182004 | D8: 1526.45
A9: HPL 53 | B9: Kompresör ZP 233 KZE - TED | C9: R20KMZP233001 | D9: 2394.46
A10: HPL 64 | B10: Kompresör ZP 293 KCE-TED | C10: R20KMZP293001 | D10: 2283.56
A11: HPL 90 | B11: Kompresör ZP385KCE-TWD 15/8x13/8 | C11: R20V206734780 | D11: 2702.18
A12: HPL 7 | B12: Copeland Karter Isıtıcı ID:8561150 | C12: R20KI08561150 | D12: 39.921
A13: HPL 11 | B13: Copeland Karter Isıtıcı ID:8561105 | C13: R20KI08561105 | D13: 40.7085
A14: HPL 15 | B14: Copeland Karter Isıtıcı ID:8561105 | C14: R20KI08561105 | D14: 40.7085
A15: HPL 22 | B15: Copeland Karter Isıtıcı ID:8561105 | C15: R20KI08561105 | D15: 40.7085
... A59: HPL 15 | B59: HPL 15 APHE H 2x1 50 4.8 134 | C59: R09HPL1525481 | D59: 986.3
A60: HPL 22 | B60: HPL 22 H2E0850-1002-060-2EDB-2-0-1-1222 | C60: R09H2E8501002 | D60: =1040*1.28 -> 1331.2
A61: HPL 32 | B61: HPL 32 H2E0850-1250-060-2EDB-2-2-1-1528 | C61: R09H2E8501250 | D61: =1269*1.28 -> 1624.32
A62: HPL 42 | B62: HPL 42 H2E0850-1506-060-2EDB-2-2-1-1834 | C62: R09PLI4201834 | D62: =1471*1.28 -> 1882.88
A63: HPL 53 | B63: HPL 53 H2E0850-1506-060-2EDB-2-2-1-1834 | C63: R09PLI5301834 | D63: =1471*1.28 -> 1882.88
A64: HPL 64 | B64: HPL 64 H2E1000-1762-060-2EDB-2-2-1-2140 | C64: R09H2E0602140 | D64: 2682.88
A65: HPL 90 | B65: HPL 90 H2E1400-1752-060-2EDB-2-3-1-2140 | C65: R09H2E0601752 | D65: =4584.58*1.28 -> 5868.2624
A66: HPL 7 | B66: HPL 7 ISITICI 32x28-1/2 C S 12T 2R 615A 3P 2NC | C66: R063228122615 | D66: 250
A67: HPL 11 | B67: ISITICI F 32x28-12 C S 12T 2R 920A 3P 3NC | C67: R063228122920 | D67: 275
A68: HPL 15 | B68: ISITICI F 32x28-12 C S 12T 2R 1220A 3P 4NC | C68: R063228122220 | D68: 310
A69: HPL 22 | B69: ISITICI F 32x28-12 C S 26T 2R 1070A 3.2P 5NC | C69: - | D69: 410
A70: HPL 32 | B70: ISITICI F 32x28-12 C S 26T 2R 1360A 3.2P 8NC | C70: - | D70: 460
A71: HPL 42 | B71: ISITICI F 32x28-12 C S 26T 2R 1660A 2.5P 8NC | C71: - | D71: 490
A72: HPL 53 | B72: ISITICI F 32x28-12 C S 31T 2R 1640A 3.2P 13NC | C72: - | D72: 580
A73: HPL 64 | B73: ISITICI F 32x28-12 C S 31T 2R 1955A 3.2P 13NC | C73: - | D73: 645
A74: HPL 90 | B74: ISITICI F 32x28-12 C S 45T 2R 1955A 3.2P 15NC | C74: - | D74: 890
A75: HPL 22 | B75: HPL22SOG32x28-1/2CS26T4R1030A2.1P26NC | C75: R06HPL2200004 | D75: 660
A76: HPL 32 | B76: HPL32SOG32x28-1/2CS26T4R1320A2.1P26NC | C76: R06HPL3200004 | D76: 825
A77: HPL 42 | B77: HPL42SOG F 32x28-12 C S 26T 4R 1620A 2.1P 36NC | C77: - | D77: 960
... A100: HPL 7 | B100: CAREL E2VSTA0201 BIPOLAR STATOR FOR E2VB | C100: R27E2V0220100 | D100: 40.53
A101: HPL 11 | B101: CAREL E2V24FSFC0 ELECTRONIC EXPANSION VALVE E2V24-F 12-12 ODF W/O STATOR | C101: R27CRLE2V2412
A102: HPL 11 | B102: CAREL E2VSTA0201 BIPOLAR STATOR FOR E2VB | C102: R27E2V0220100 | D102: 40.53
A103: HPL 15 | B103: CAREL E2V30FSFC0 ELECTRONIC EXPANSION VALVE E2V30-F 12-12 ODF W/O STATOR | C103: R27CRLE2V3012
A104: HPL 15 | B104: CAREL E2VSTA0201 BIPOLAR STATOR FOR E2VB | C104: R27E2V0220100 | D104: 40.53
A105: HPL 22 | B105: CAREL E2V18FSFC0 ELECTRONIC EXPANSION VALVE E2V18-F 12-12 ODF W/O STATOR | C105: R27CRLE2V1812 | D105: 77.46
A106: HPL 22 | B106: CAREL E2VSTA0201 BIPOLAR STATOR FOR E2VB | C106: R27E2V0220100 | D106: 40.53
...

Sheet 7
B1: Model | C1: Yön | D1: Besleme Filtre | E1: Dönüş Filtre | F1: Soğutucu Batarya | G1: Dış Ortam | H1: Ön Isıtıcı | I1: TCP/IP | N1: HPL 7
M2: No | N2: MALZEME ADI | O2: ERP KODU | P2: BİRİM | Q2: MİKTAR | R2: Birim Fiyat | S2: Toplam Fiyat
B3: 7 | C3: sabit | D3: sabit | E3: sabit | F3: sabit | G3: sabit | H3: sabit | I3: sabit | J3: =SUBTOTAL(103,B3) -> 1 | L3: MEKANİK | M3: 1 | N3: Kompresör ZP36K5E-TFD | O3: R20KMZP036K5E | P3: Adet | Q3: 1 | R3: =VLOOKUP('7'!O3,Malzemeler!C:D,2,0) -> 1 | S3: =+R3*Q3 -> 1
B4: 7 | C4: sabit | D4: sabit | E4: sabit | F4: sabit | G4: sabit | H4: sabit | I4: sabit | J4: =SUBTOTAL(103,B4) -> 1 | L4: MEKANİK | M4: 2 | N4: Copeland Karter Isıtıcı ID:8561150 | O4: R20KI08561150 | P4: Adet | Q4: 1 | R4: =VLOOKUP('7'!O4,Malzemeler!C:D,2,0) -> 39.921 | S4: =+R4*Q4 -> 39.921
B5: 7 | C5: sabit | D5: sabit | E5: sabit | F5: sabit | G5: sabit | H5: sabit | I5: sabit | J5: =SUBTOTAL(103,B5) -> 1 | L5: MEKANİK | M5: 3 | N5: 4 Yollu Vana SHF-14A-46 1/2"x3/4" | O5: R20V144612340 | P5: Adet | Q5: 1 | R5: =VLOOKUP('7'!O5,Malzemeler!C:D,2,0) -> 60 | S5: =+R5*Q5 -> 60
B6: 7 | C6: sabit | D6: sabit | E6: sabit | F6: sabit | G6: sabit | H6: sabit | I6: sabit | J6: =SUBTOTAL(103,B6) -> 1 | L6: MEKANİK | M6: 4 | N6: 4 Yollu Vana Bobini 220V AC 4,5W Kablolu | O6: R27SVB2204500 | P6: Adet | Q6: 1 | R6: =VLOOKUP('7'!O6,Malzemeler!C:D,2,0) -> 12.8 | S6: =+R6*Q6 -> 12.8
B7: 7 | C7: sabit | D7: sabit | E7: sabit | F7: sabit | G7: sabit | H7: sabit | I7: sabit | J7: =SUBTOTAL(103,B7) -> 1 | L7: MEKANİK | M7: 5 | N7: Danfoss NRV 10 s 02B1011 3/8" Check Valve | O7: R20NRV10S3801 | P7: Adet | Q7: 4 | R7: =VLOOKUP('7'!O7,Malzemeler!C:D,2,0) -> 13.05 | S7: =+R7*Q7 -> 52.2
B8: 7 | C8: sabit | D8: sabit | E8: sabit | F8: sabit | G8: sabit | H8: sabit | I8: sabit | J8: =SUBTOTAL(103,B8) -> 1 | L8: MEKANİK | M8: 6 | N8: Danfoss Drier DML083 3/8" 023Z5040 | O8: R20DML0833801 | P8: Adet | Q8: 1 | R8: =VLOOKUP('7'!O8,Malzemeler!C:D,2,0) -> 10.15 | S8: =+R8*Q8 -> 10.15
B9: 7 | C9: sabit | D9: sabit | E9: sabit | F9: sabit | G9: sabit | H9: sabit | I9: sabit | J9: =SUBTOTAL(103,B9) -> 1 | L9: MEKANİK | M9: 7 | N9: Danfoss Gözetleme Camı Kaynaklı SGP 10s N 3/8" 014L0182 | O9: R20SGP10SN380 | P9: Adet | Q9: 1 | R9: =VLOOKUP('7'!O9,Malzemeler!C:D,2,0) -> 9.5 | S9: =+R9*Q9 -> 9.5
B10: 7 | C10: sabit | D10: sabit | E10: sabit | F10: sabit | G10: sabit | H10: sabit | I10: sabit | J10: =SUBTOTAL(103,B10) -> 1 | L10: MEKANİK | M10: 8 | N10: Danfoss Küresel Vana GBC 10s 3/8" 009L7021 | O10: R20GBC1038702 | P10: Adet | Q10: 1 | R10: =VLOOKUP('7'!O10,Malzemeler!C:D,2,0) -> 18 | S10: =+R10*Q10 -> 18
B11: 7 | C11: sabit | D11: sabit | E11: sabit | F11: sabit | G11: sabit | H11: sabit | I11: sabit | J11: =SUBTOTAL(103,B11) -> 1 | L11: MEKANİK | M11: 9 | N11: GVN LİKİT TANKI VLR.A.33b.02.B2.C2 | O11: R20LTVLR02221 | P11: Adet | Q11: 1 | R11: =VLOOKUP('7'!O11,Malzemeler!C:D,2,0) -> 0 | S11: =+R11*Q11 -> 0
B12: 7 | C12: sabit | D12: sabit | E12: sabit | F12: sabit | G12: sabit | H12: sabit | I12: sabit | J12: =SUBTOTAL(103,B12) -> 1 | L12: MEKANİK | M12: 10 | N12: GVN EMİŞ AKÜMÜLATÖRÜ SLA.33B.19.1.7 | O12: R20SLA1917000 | P12: Adet | Q12: 1 | R12: =VLOOKUP('7'!O12,Malzemeler!C:D,2,0) -> 0 | S12: =+R12*Q12 -> 0
B13: 7 | C13: sabit | D13: sabit | E13: sabit | F13: sabit | G13: sabit | H13: sabit | I13: sabit | J13: =SUBTOTAL(103,B13) -> 1 | L13: MEKANİK | M13: 11 | N13: BAKIR BORU Q19 (3/4")-1 MM | O13: R20BBQ1900000 | P13: Adet | Q13: 4 | R13: =VLOOKUP('7'!O13,Malzemeler!C:D,2,0) -> 9.65 | S13: =+R13*Q13 -> 38.6
B14: 7 | C14: sabit | D14: sabit | E14: sabit | F14: sabit | G14: sabit | H14: sabit | I14: sabit | J14: =SUBTOTAL(103,B14) -> 1 | L14: MEKANİK | M14: 12 | N14: BAKIR BORU Q9,52 (3/8")-1 MM | O14: R20BBQ9520000 | P14: Adet | Q14: 3.5 | R14: =VLOOKUP('7'!O14,Malzemeler!C:D,2,0) -> 4.65 | S14: =+R14*Q14 -> 16.275
... B86: 7 | C86: sabit | D86: sabit | E86: sabit | F86: sabit | G86: sabit | H86: sabit | I86: sabit | J86: =SUBTOTAL(103,B86) -> 1 | L86: OTOMASYON | M86: 84 | N86: LIHCH KABLO 2X0,75 | O86: R12KBLIHCH2X0 | P86: Metre | Q86: 45 | R86: =VLOOKUP('7'!O86,Malzemeler!C:D,2,0) -> 0 | S86: =+R86*Q86 -> 0
B87: 7 | C87: sabit | D87: sabit | E87: sabit | F87: sabit | G87: sabit | H87: sabit | I87: 1 | J87: =SUBTOTAL(103,B87) -> 1 | L87: TCP IP | M87: 1 | N87: pCOweb SE, ethernet card IP protocols pco1000wd | O87: R278003303311 | P87: Adet | Q87: 1 | R87: =VLOOKUP('7'!O87,Malzemeler!C:D,2,0) -> 0 | S87: =+R87*Q87 -> 0

Sheet 11
B1: Model | C1: Yön | D1: Besleme Filtre | E1: Dönüş Filtre | F1: Soğutucu Batarya | G1: Dış Ortam | H1: Ön Isıtıcı | I1: TCP/IP | N1: HPL 11
M2: No | N2: MALZEME ADI | O2: ERP KODU | P2: BİRİM | Q2: MİKTAR | R2: BİRİM FİYAT | S2: TOPLAM FİYAT
B3: 11 | C3: sabit | D3: sabit | E3: sabit | F3: sabit | G3: sabit | H3: sabit | I3: sabit | J3: =SUBTOTAL(103,B3) -> 1 | L3: MEKANİK | M3: 1 | N3: Kompresör ZP61 K5E TFD 522 | O3: R20KMZP61K001 | P3: Adet | Q3: 1 | R3: =VLOOKUP('11'!O3,Malzemeler!C:D,2,0) -> 629.96 | S3: =+R3*Q3 -> 629.96
B4: 11 | C4: sabit | D4: sabit | E4: sabit | F4: sabit | G4: sabit | H4: sabit | I4: sabit | J4: =SUBTOTAL(103,B4) -> 1 | L4: MEKANİK | M4: 2 | N4: Copeland Karter Isıtıcı ID:8561105 | O4: R20KI08561105 | P4: Adet | Q4: 1 | R4: =VLOOKUP('11'!O4,Malzemeler!C:D,2,0) -> 40.7085 | S4: =+R4*Q4 -> 40.7085
B5: 11 | C5: sabit | D5: sabit | E5: sabit | F5: sabit | G5: sabit | H5: sabit | I5: sabit | J5: =SUBTOTAL(103,B5) -> 1 | L5: MEKANİK | M5: 3 | N5: 4 Yollu Vana SHF-14A-46 1/2"x3/4" | O5: R20V144612340 | P5: Adet | Q5: 1 | R5: =VLOOKUP('11'!O5,Malzemeler!C:D,2,0) -> 60 | S5: =+R5*Q5 -> 60
B6: 11 | C6: sabit | D6: sabit | E6: sabit | F6: sabit | G6: sabit | H6: sabit | I6: sabit | J6: =SUBTOTAL(103,B6) -> 1 | L6: MEKANİK | M6: 4 | N6: 4 Yollu Vana Bobini 220V AC 4,5W Kablolu | O6: R27SVB2204500 | P6: Adet | Q6: 1 | R6: =VLOOKUP('11'!O6,Malzemeler!C:D,2,0) -> 12.8 | S6: =+R6*Q6 -> 12.8
B7: 11 | C7: sabit | D7: sabit | E7: sabit | F7: sabit | G7: sabit | H7: sabit | I7: sabit | J7: =SUBTOTAL(103,B7) -> 1 | L7: MEKANİK | M7: 5 | N7: Danfoss NRV 12 s 020B1012 1/2" Check Valve | O7: R20NRV12S1201 | P7: Adet | Q7: 4 | R7: =VLOOKUP('11'!O7,Malzemeler!C:D,2,0) -> 14 | S7: =+R7*Q7 -> 56
B8: 11 | C8: sabit | D8: sabit | E8: sabit | F8: sabit | G8: sabit | H8: sabit | I8: sabit | J8: =SUBTOTAL(103,B8) -> 1 | L8: MEKANİK | M8: 6 | N8: Danfoss Drier DML164 1/2" 023Z5044 | O8: R20DML1641201 | P8: Adet | Q8: 1 | R8: =VLOOKUP('11'!O8,Malzemeler!C:D,2,0) -> 10.8 | S8: =+R8*Q8 -> 10.8
B9: 11 | C9: sabit | D9: sabit | E9: sabit | F9: sabit | G9: sabit | H9: sabit | I9: sabit | J9: =SUBTOTAL(103,B9) -> 1 | L9: MEKANİK | M9: 7 | N9: Danfoss Gözetleme Camı Kaynaklı SGP 12s N 1/2" 014L0183 | O9: R20SPG12SN120 | P9: Adet | Q9: 1 | R9: =VLOOKUP('11'!O9,Malzemeler!C:D,2,0) -> 10.8 | S9: =+R9*Q9 -> 10.8
B10: 11 | C10: sabit | D10: sabit | E10: sabit | F10: sabit | G10: sabit | H10: sabit | I10: sabit | J10: =SUBTOTAL(103,B10) -> 1 | L10: MEKANİK | M10: 8 | N10: Danfoss Küresel Vana GBC 12s 1/2" 009L7022 | O10: R20GBC1212702 | P10: Adet | Q10: 1 | R10: =VLOOKUP('11'!O10,Malzemeler!C:D,2,0) -> 18 | S10: =+R10*Q10 -> 18
B11: 11 | C11: sabit | D11: sabit | E11: sabit | F11: sabit | G11: sabit | H11: sabit | I11: sabit | J11: =SUBTOTAL(103,B11) -> 1 | L11: MEKANİK | M11: 9 | N11: GVN LİKİT TANKI VLR.A.33b.03.B2.C2 | O11: R20LTVLR02322 | P11: Adet | Q11: 1 | R11: =VLOOKUP('11'!O11,Malzemeler!C:D,2,0) -> 0 | S11: =+R11*Q11 -> 0
B12: 11 | C12: sabit | D12: sabit | E12: sabit | F12: sabit | G12: sabit | H12: sabit | I12: sabit | J12: =SUBTOTAL(103,B12) -> 1 | L12: MEKANİK | M12: 10 | N12: GVN EMİŞ AKÜMÜLATÖRÜ SLA.33B.19.1.7 | O12: R20SLA1917000 | P12: Adet | Q12: 1 | R12: =VLOOKUP('11'!O12,Malzemeler!C:D,2,0) -> 0 | S12: =+R12*Q12 -> 0
B13: 11 | C13: sabit | D13: sabit | E13: sabit | F13: sabit | G13: sabit | H13: sabit | I13: sabit | J13: =SUBTOTAL(103,B13) -> 1 | L13: MEKANİK | M13: 11 | N13: BAKIR Q12 Boru (1/2") -1 mm | O13: R20BBQ1200000 | P13: Adet | Q13: 5.3 | R13: =VLOOKUP('11'!O13,Malzemeler!C:D,2,0) -> 6.35 | S13: =+R13*Q13 -> 33.655
B14: 11 | C14: sabit | D14: sabit | E14: sabit | F14: sabit | G14: sabit | H14: sabit | I14: sabit | J14: =SUBTOTAL(103,B14) -> 1 | L14: MEKANİK | M14: 12 | N14: BAKIR BORU 1/4" | O14: R20BBQ1400000 | P14: Adet | Q14: 4 | R14: =VLOOKUP('11'!O14,Malzemeler!C:D,2,0) -> 2.5 | S14: =+R14*Q14 -> 10
... B20: 11 | C20: sabit | D20: sabit | E20: sabit | F20: sabit | G20: sabit | H20: sabit | I20: sabit | J20: =SUBTOTAL(103,B20) -> 1 | L20: MEKANİK | M20: 18 | N20: BAKIR TE 1/2"-1/2"-1/2" | O20: R20BT00121212 | P20: Adet | Q20: 6 | R20: =VLOOKUP('11'!O20,Malzemeler!C:D,2,0) -> 0.45 | S20: =+R20*Q20 -> 2.7
B21: 11 | C21: sabit | D21: sabit | E21: sabit | F21: sabit | G21: sabit | H21: sabit | I21: sabit | J21: =SUBTOTAL(103,B21) -> 1 | L21: MEKANİK | M21: 18 | N21: Kauçuk Kelepçe 22 mm | O21: R21RK32000002 | P21: Adet | Q21: 2 | R21: =VLOOKUP('7'!O21,Malzemeler!C:D,2,0) -> 0.4 | S21: =+R21*Q21 -> 0.8
B22: 11 | C22: sabit | D22: sabit | E22: sabit | F22: sabit | G22: sabit | H22: sabit | I22: sabit | J22: =SUBTOTAL(103,B22) -> 1 | L22: MEKANİK | M22: 19 | N22: 7/8" İzolasyon 9'luk | O22: R10IZ90280005 | P22: Adet | Q22: 3 | R22: =VLOOKUP('11'!O22,Malzemeler!C:D,2,0) -> 0.4 | S22: =+R22*Q22 -> 1.2
B23: 11 | C23: sabit | D23: sabit | E23: sabit | F23: sabit | G23: sabit | H23: sabit | I23: sabit | J23: =SUBTOTAL(103,B23) -> 1 | L23: MEKANİK | M23: 20 | N23: Gümüş KAYNAK TELİ | O23: R20GK30000000 | P23: Adet | Q23: 0.2 | R23: =VLOOKUP('11'!O23,Malzemeler!C:D,2,0) -> 1615.6 | S23: =+R23*Q23 -> 323.12
B24: 11 | C24: sabit | D24: sabit | E24: sabit | F24: sabit | G24: sabit | H24: sabit | I24: sabit | J24: =SUBTOTAL(103,B24) -> 1 | L24: MEKANİK | M24: 21 | N24: BAKIR KAYNAK TELİ | O24: R20BAKIRKT001 | P24: Adet | Q24: 0.2 | R24: =VLOOKUP('11'!O24,Malzemeler!C:D,2,0) -> 40 | S24: =+R24*Q24 -> 8
B25: 11 | C25: sabit | D25: sabit | E25: sabit | F25: sabit | G25: sabit | H25: sabit | I25: sabit | J25: =SUBTOTAL(103,B25) -> 1 | L25: MEKANİK | M25: 22 | N25: BORAKS KİMYASAL ICOLD İ-FLUX 020AG1014 | O25: R20BR10000000 | P25: Adet | Q25: 0.1 | R25: =VLOOKUP('11'!O25,Malzemeler!C:D,2,0) -> 150 | S25: =+R25*Q25 -> 15
B26: 11 | C26: sabit | D26: sabit | E26: sabit | F26: sabit | G26: sabit | H26: sabit | I26: sabit | J26: =SUBTOTAL(103,B26) -> 1 | L26: MEKANİK | M26: 23 | N26: CRYOLANT RB 32 ESTER YAG | O26: R20KY0RB32001 | P26: Adet | Q26: 0.8 | R26: =VLOOKUP('11'!O26,Malzemeler!C:D,2,0) -> 30 | S26: =+R26*Q26 -> 24
B27: 11 | C27: sabit | D27: sabit | E27: sabit | F27: sabit | G27: sabit | H27: sabit | I27: sabit | J27: =SUBTOTAL(103,B27) -> 1 | L27: MEKANİK | M27: 24 | N27: GAZ R410 (11.3 KG/TÜP) | O27: R20GR41000000 | P27: Adet | Q27: 1 | R27: =VLOOKUP('11'!O27,Malzemeler!C:D,2,0) -> 150 | S27: =+R27*Q27 -> 150
B28: 11 | C28: sabit | D28: sabit | E28: sabit | F28: sabit | G28: sabit | H28: sabit | I28: sabit | J28: =SUBTOTAL(103,B28) -> 1 | L28: MEKANİK | M28: 25 | N28: 8300100054-VBH0355CTPMS/S | O28: R058300100054 | P28: Adet | Q28: 1 | R28: =VLOOKUP('11'!O28,Malzemeler!C:D,2,0) -> 370 | S28: =+R28*Q28 -> 370
B29: 11 | C29: sabit | D29: sabit | E29: sabit | F29: sabit | G29: sabit | H29: sabit | I29: sabit | J29: =SUBTOTAL(103,B29) -> 1 | L29: MEKANİK | M29: 26 | N29: 8300100054-VBH0355CTPMS/S | O29: R058300100054 | P29: Adet | Q29: 1 | R29: =VLOOKUP('11'!O29,Malzemeler!C:D,2,0) -> 370 | S29: =+R29*Q29 -> 370
B30: 11 | C30: sabit | D30: sabit | E30: sabit | F30: sabit | G30: sabit | H30: sabit | I30: sabit | J30: =SUBTOTAL(103,B30) -> 1 | L30: MEKANİK | M30: 27 | N30: HPL 11 APHE H 2x1 50 4.8 103 | O30: R09HPL1125048 | P30: Adet | Q30: 1 | R30: =VLOOKUP('11'!O30,Malzemeler!C:D,2,0) -> 760.2 | S30: =+R30*Q30 -> 760.2
B31: 11 | C31: sabit | D31: sabit | E31: sabit | F31: sabit | G31: sabit | H31: sabit | I31: sabit | J31: =SUBTOTAL(103,B31) -> 1 | L31: MEKANİK | M31: 28 | N31: ISITICI F 32x28-12 C S 12T 2R 920A 3P 3NC | O31: R063228122920 | P31: Adet | Q31: 1 | R31: =VLOOKUP('11'!O31,Malzemeler!C:D,2,0) -> 275 | S31: =+R31*Q31 -> 275
B32: 11 | C32: sabit | D32: sabit | E32: sabit | F32: sabit | G32: sabit | H32: sabit | I32: sabit | J32: =SUBTOTAL(103,B32) -> 1 | L32: MEKANİK | M32: 29 | N32: KONDENSER F 32x28-12 C S 15T 6R 915A 2.1P 5NC | O32: R063228121569 | P32: Adet | Q32: 1 | R32: =VLOOKUP('11'!O32,Malzemeler!C:D,2,0) -> 585 | S32: =+R32*Q32 -> 585
B33: 11 | C33: sabit | D33: sabit | E33: sabit | F33: sabit | G33: sabit | H33: sabit | I33: sabit | J33: =SUBTOTAL(103,B33) -> 1 | L33: MEKANİK | M33: 30 | N33: EVAPARATÖR F 32x28-12 C S 15T 4R 915A 2.4P 6NC | O33: R063228121549 | P33: Adet | Q33: 1 | R33: =VLOOKUP('11'!O33,Malzemeler!C:D,2,0) -> 480 | S33: =+R33*Q33 -> 480
... B89: 11 | C89: sabit | D89: sabit | E89: sabit | F89: sabit | G89: sabit | H89: sabit | I89: sabit | J89: =SUBTOTAL(103,B89) -> 1 | L89: OTOMASYON | M89: 86 | N89: LIHCH KABLO 2X0,75 | O89: R12KBLIHCH2X0 | P89: Metre | Q89: 45 | R89: =VLOOKUP('11'!O89,Malzemeler!C:D,2,0) -> 0 | S89: =+R89*Q89 -> 0
B90: 11 | C90: sabit | D90: sabit | E90: sabit | F90: sabit | G90: sabit | H90: sabit | I90: 1 | J90: =SUBTOTAL(103,B90) -> 1 | L90: TCP IP | M90: 1 | N90: pCOweb SE, ethernet card IP protocols pco1000wd | O90: R278003303311 | P90: Adet | Q90: 1 | R90: =VLOOKUP('11'!O90,Malzemeler!C:D,2,0) -> 0 | S90: =+R90*Q90 -> 0

Sheet 15
B1: Model | C1: Yön | D1: Besleme Filtre | E1: Dönüş Filtre | F1: Soğutucu Batarya | G1: Dış Ortam | H1: Ön Isıtıcı | I1: TCP/IP | N1: HPL 15
B2: 15 | C2: sabit | D2: sabit | E2: sabit | F2: sabit | G2: sabit | H2: sabit | I2: sabit | J2: =SUBTOTAL(103,B2) -> 1 | M2: No | N2: MALZEME ADI | O2: ERP KODU | P2: BİRİM | Q2: MİKTAR | R2: BİRİM FİYAT | S2: TOPLAM FİYAT
B3: 15 | C3: sabit | D3: sabit | E3: sabit | F3: sabit | G3: sabit | H3: sabit | I3: sabit | J3: =SUBTOTAL(103,B3) -> 1 | L3: MEKANİK | M3: 1 | N3: Kompresör ZP91KCE-TFD 3/4x7/8 | O3: R20KMZP053400 | P3: Adet | Q3: 1 | R3: =VLOOKUP('15'!O3,Malzemeler!C:D,2,0) -> 906.12 | S3: =+R3*Q3 -> 906.12
B4: 15 | C4: sabit | D4: sabit | E4: sabit | F4: sabit | G4: sabit | H4: sabit | I4: sabit | J4: =SUBTOTAL(103,B4) -> 1 | L4: MEKANİK | M4: 2 | N4: Copeland Karter Isıtıcı ID:8561105 | O4: R20KI08561105 | P4: Adet | Q4: 1 | R4: =VLOOKUP('15'!O4,Malzemeler!C:D,2,0) -> 40.7085 | S4: =+R4*Q4 -> 40.7085
B5: 15 | C5: sabit | D5: sabit | E5: sabit | F5: sabit | G5: sabit | H5: sabit | I5: sabit | J5: =SUBTOTAL(103,B5) -> 1 | L5: MEKANİK | M5: 3 | N5: 4 Yollu Vana SHF-20A-67 3/4"x7/8" | O5: R20V206734780 | P5: Adet | Q5: 1 | R5: =VLOOKUP('15'!O5,Malzemeler!C:D,2,0) -> 2702.18 | S5: =+R5*Q5 -> 2702.18
B6: 15 | C6: sabit | D6: sabit | E6: sabit | F6: sabit | G6: sabit | H6: sabit | I6: sabit | J6: =SUBTOTAL(103,B6) -> 1 | L6: MEKANİK | M6: 4 | N6: 4 Yollu Vana Bobini 220V AC 4,5W Kablolu | O6: R27SVB2204500 | P6: Adet | Q6: 1 | R6: =VLOOKUP('15'!O6,Malzemeler!C:D,2,0) -> 12.8 | S6: =+R6*Q6 -> 12.8
B7: 15 | C7: sabit | D7: sabit | E7: sabit | F7: sabit | G7: sabit | H7: sabit | I7: sabit | J7: =SUBTOTAL(103,B7) -> 1 | L7: MEKANİK | M7: 5 | N7: Danfoss NRV 16 s 020B1018 5/8" Check Valve | O7: R20NRV16S5801 | P7: Adet | Q7: 4 | R7: =VLOOKUP('15'!O7,Malzemeler!C:D,2,0) -> 16.7 | S7: =+R7*Q7 -> 66.8
B8: 15 | C8: sabit | D8: sabit | E8: sabit | F8: sabit | G8: sabit | H8: sabit | I8: sabit | J8: =SUBTOTAL(103,B8) -> 1 | L8: MEKANİK | M8: 6 | N8: Danfoss Drier DML165 5/8" 023Z5045 | O8: R20DML1655801 | P8: Adet | Q8: 1 | R8: =VLOOKUP('15'!O8,Malzemeler!C:D,2,0) -> 10.8 | S8: =+R8*Q8 -> 10.8
B9: 15 | C9: sabit | D9: sabit | E9: sabit | F9: sabit | G9: sabit | H9: sabit | I9: sabit | J9: =SUBTOTAL(103,B9) -> 1 | L9: MEKANİK | M9: 7 | N9: Danfoss Gözetleme Camı Kaynaklı SGP 16s N 5/8" 014L0145 | O9: R20SGP16SN580 | P9: Adet | Q9: 1 | R9: =VLOOKUP('15'!O9,Malzemeler!C:D,2,0) -> 14.5 | S9: =+R9*Q9 -> 14.5
B10: 15 | C10: sabit | D10: sabit | E10: sabit | F10: sabit | G10: sabit | H10: sabit | I10: sabit | J10: =SUBTOTAL(103,B10) -> 1 | L10: MEKANİK | M10: 8 | N10: Danfoss Küresel Vana GBC 16s 5/8" 009L7023 | O10: R20GBC1658723 | P10: Adet | Q10: 1 | R10: =VLOOKUP('15'!O10,Malzemeler!C:D,2,0) -> 19.5 | S10: =+R10*Q10 -> 19.5
B11: 15 | C11: sabit | D11: sabit | E11: sabit | F11: sabit | G11: sabit | H11: sabit | I11: sabit | J11: =SUBTOTAL(103,B11) -> 1 | L11: MEKANİK | M11: 9 | N11: GVN LİKİT TANKI VLR.A.33b.04.B2.C2 | O11: R20LTVLR02423 | P11: Adet | Q11: 1 | R11: =VLOOKUP('15'!O11,Malzemeler!C:D,2,0) -> 0 | S11: =+R11*Q11 -> 0
B12: 15 | C12: sabit | D12: sabit | E12: sabit | F12: sabit | G12: sabit | H12: sabit | I12: sabit | J12: =SUBTOTAL(103,B12) -> 1 | L12: MEKANİK | M12: 10 | N12: GVN EMİŞ AKÜMÜLATÖRÜ SLA.33B.22.3.5 | O12: R20SLA2235000 | P12: Adet | Q12: 1 | R12: =VLOOKUP('15'!O12,Malzemeler!C:D,2,0) -> 0 | S12: =+R12*Q12 -> 0
B13: 15 | C13: sabit | D13: sabit | E13: sabit | F13: sabit | G13: sabit | H13: sabit | I13: sabit | J13: =SUBTOTAL(103,B13) -> 1 | L13: MEKANİK | M13: 11 | N13: BAKIR BORU 1/4" | O13: R20BBQ1400000 | P13: Adet | Q13: 5.5 | R13: =VLOOKUP('15'!O13,Malzemeler!C:D,2,0) -> 2.5 | S13: =+R13*Q13 -> 13.75
B14: 15 | C14: sabit | D14: sabit | E14: sabit | F14: sabit | G14: sabit | H14: sabit | I14: sabit | J14: =SUBTOTAL(103,B14) -> 1 | L14: MEKANİK | M14: 12 | N14: BAKIR BORU Q16 (5/8")-1 MM | O14: R20BBQ1600000 | P14: Adet | Q14: 5 | R14: =VLOOKUP('15'!O14,Malzemeler!C:D,2,0) -> 7.85 | S14: =+R14*Q14 -> 39.25
... B20: 15 | C20: sabit | D20: sabit | E20: sabit | F20: sabit | G20: sabit | H20: sabit | I20: sabit | J20: =SUBTOTAL(103,B20) -> 1 | L20: MEKANİK | M20: 18 | N20: BAKIR TE 1/2"-1/2"-1/2" | O20: R20BT00121212 | P20: Adet | Q20: 6 | R20: =VLOOKUP('15'!O20,Malzemeler!C:D,2,0) -> 0.45 | S20: =+R20*Q20 -> 2.7
B21: 15 | C21: sabit | D21: sabit | E21: sabit | F21: sabit | G21: sabit | H21: sabit | I21: sabit | J21: =SUBTOTAL(103,B21) -> 1 | L21: MEKANİK | M21: 18 | N21: Kauçuk Kelepçe 22 mm | O21: R21RK32000002 | P21: Adet | Q21: 2 | R21: =VLOOKUP('7'!O21,Malzemeler!C:D,2,0) -> 0.4 | S21: =+R21*Q21 -> 0.8
B22: 15 | C22: sabit | D22: sabit | E22: sabit | F22: sabit | G22: sabit | H22: sabit | I22: sabit | J22: =SUBTOTAL(103,B22) -> 1 | L22: MEKANİK | M22: 19 | N22: 7/8" İzolasyon 9'luk | O22: R10IZ90280005 | P22: Adet | Q22: 4 | R22: =VLOOKUP('15'!O22,Malzemeler!C:D,2,0) -> 0.4 | S22: =+R22*Q22 -> 1.6
B23: 15 | C23: sabit | D23: sabit | E23: sabit | F23: sabit | G23: sabit | H23: sabit | I23: sabit | J23: =SUBTOTAL(103,B23) -> 1 | L23: MEKANİK | M23: 20 | N23: Gümüş KAYNAK TELİ | O23: R20GK30000000 | P23: Adet | Q23: 0.3 | R23: =VLOOKUP('15'!O23,Malzemeler!C:D,2,0) -> 1615.6 | S23: =+R23*Q23 -> 484.68
B24: 15 | C24: sabit | D24: sabit | E24: sabit | F24: sabit | G24: sabit | H24: sabit | I24: sabit | J24: =SUBTOTAL(103,B24) -> 1 | L24: MEKANİK | M24: 21 | N24: BAKIR KAYNAK TELİ | O24: R20BAKIRKT001 | P24: Adet | Q24: 0.3 | R24: =VLOOKUP('15'!O24,Malzemeler!C:D,2,0) -> 40 | S24: =+R24*Q24 -> 12
B25: 15 | C25: sabit | D25: sabit | E25: sabit | F25: sabit | G25: sabit | H25: sabit | I25: sabit | J25: =SUBTOTAL(103,B25) -> 1 | L25: MEKANİK | M25: 22 | N25: BORAKS KİMYASAL ICOLD İ-FLUX 020AG1014 | O25: R20BR10000000 | P25: Adet | Q25: 0.1 | R25: =VLOOKUP('15'!O25,Malzemeler!C:D,2,0) -> 150 | S25: =+R25*Q25 -> 15
B26: 15 | C26: sabit | D26: sabit | E26: sabit | F26: sabit | G26: sabit | H26: sabit | I26: sabit | J26: =SUBTOTAL(103,B26) -> 1 | L26: MEKANİK | M26: 23 | N26: CRYOLANT RB 32 ESTER YAG | O26: R20KY0RB32001 | P26: Adet | Q26: 0.8 | R26: =VLOOKUP('15'!O26,Malzemeler!C:D,2,0) -> 30 | S26: =+R26*Q26 -> 24
B27: 15 | C27: sabit | D27: sabit | E27: sabit | F27: sabit | G27: sabit | H27: sabit | I27: sabit | J27: =SUBTOTAL(103,B27) -> 1 | L27: MEKANİK | M27: 24 | N27: GAZ R410 (11.3 KG/TÜP) | O27: R20GR41000000 | P27: Adet | Q27: 1 | R27: =VLOOKUP('15'!O27,Malzemeler!C:D,2,0) -> 150 | S27: =+R27*Q27 -> 150
B28: 15 | C28: sabit | D28: sabit | E28: sabit | F28: sabit | G28: sabit | H28: sabit | I28: sabit | J28: =SUBTOTAL(103,B28) -> 1 | L28: MEKANİK | M28: 25 | N28: 8300102231-VBH0400CTRNZ | O28: R058300102231 | P28: Adet | Q28: 1 | R28: =VLOOKUP('15'!O28,Malzemeler!C:D,2,0) -> 0 | S28: =+R28*Q28 -> 0
B29: 15 | C29: sabit | D29: sabit | E29: sabit | F29: sabit | G29: sabit | H29: sabit | I29: sabit | J29: =SUBTOTAL(103,B29) -> 1 | L29: MEKANİK | M29: 26 | N29: 8300102231-VBH0400CTRNZ | O29: R058300102231 | P29: Adet | Q29: 1 | R29: =VLOOKUP('15'!O29,Malzemeler!C:D,2,0) -> 0 | S29: =+R29*Q29 -> 0
B30: 15 | C30: sabit | D30: sabit | E30: sabit | F30: sabit | G30: sabit | H30: sabit | I30: sabit | J30: =SUBTOTAL(103,B30) -> 1 | L30: MEKANİK | M30: 27 | N30: HPL 15 APHE H 2x1 50 4.8 134 | O30: R09HPL1525481 | P30: Adet | Q30: 1 | R30: =VLOOKUP('15'!O30,Malzemeler!C:D,2,0) -> 986.3 | S30: =+R30*Q30 -> 986.3
B31: 15 | C31: sabit | D31: sabit | E31: sabit | F31: sabit | G31: sabit | H31: sabit | I31: sabit | J31: =SUBTOTAL(103,B31) -> 1 | L31: MEKANİK | M31: 28 | N31: ISITICI F 32x28-12 C S 12T 2R 1220A 3P 4NC | O31: R063228122220 | P31: Adet | Q31: 1 | R31: =VLOOKUP('15'!O31,Malzemeler!C:D,2,0) -> 310 | S31: =+R31*Q31 -> 310
B32: 15 | C32: sabit | D32: sabit | E32: sabit | F32: sabit | G32: sabit | H32: sabit | I32: sabit | J32: =SUBTOTAL(103,B32) -> 1 | L32: MEKANİK | M32: 29 | N32: KONDENSER F 32x28-12 C S 15T 6R 1210A 2.1P 5NC | O32: R063228121561 | P32: Adet | Q32: 1 | R32: =VLOOKUP('15'!O32,Malzemeler!C:D,2,0) -> 775 | S32: =+R32*Q32 -> 775
B33: 15 | C33: sabit | D33: sabit | E33: sabit | F33: sabit | G33: sabit | H33: sabit | I33: sabit | J33: =SUBTOTAL(103,B33) -> 1 | L33: MEKANİK | M33: 30 | N33: EVAPARATÖR F 32x28-12 C S 15T 4R 1210A 2.4P 6NC | O33: R063228121541 | P33: Adet | Q33: 1 | R33: =VLOOKUP('15'!O33,Malzemeler!C:D,2,0) -> 610 | S33: =+R33*Q33 -> 610
... B87: 15 | C87: sabit | D87: sabit | E87: sabit | F87: sabit | G87: sabit | H87: sabit | I87: sabit | J87: =SUBTOTAL(103,B87) -> 1 | L87: OTOMASYON | M87: 84 | N87: LIHCH KABLO 2X0,75 | O87: R12KBLIHCH2X0 | P87: Metre | Q87: 45 | R87: =VLOOKUP('15'!O87,Malzemeler!C:D,2,0) -> 0 | S87: =+R87*Q87 -> 0
B88: 15 | C88: sabit | D88: sabit | E88: sabit | F88: sabit | G88: sabit | H88: sabit | I88: 1 | J88: =SUBTOTAL(103,B88) -> 1 | L88: TCP IP | M88: 1 | N88: pCOweb SE, ethernet card IP protocols pco1000wd | O88: R278003303311 | P88: Adet | Q88: 1 | R88: =VLOOKUP('15'!O88,Malzemeler!C:D,2,0) -> 0 | S88: =+R88*Q88 -> 0

Sheet 22
B1: Model | C1: Yön | D1: Besleme Filtre | E1: Dönüş Filtre | F1: Soğutucu Batarya | G1: Dış Ortam | H1: Ön Isıtıcı | I1: TCP/IP | N1: HPL 22
B2: 22 | C2: sabit | D2: sabit | E2: sabit | F2: sabit | G2: sabit | H2: sabit | I2: sabit | J2: =SUBTOTAL(103,B2) -> 1 | M2: No | N2: MALZEME ADI | O2: ERP KODU | P2: BİRİM | Q2: MİKTAR | R2: BİRİM FİYAT | S2: TOPLAM FİYAT
A3: MEKANİK | B3: 22 | C3: sabit | D3: sabit | E3: sabit | F3: sabit | G3: sabit | H3: sabit | I3: sabit | J3: =SUBTOTAL(103,B3) -> 1 | L3: MEKANİK | M3: 1 | N3: Kompresör ZP104 KCE TFD 455 | O3: R20KMZP104001 | P3: Adet | Q3: 1 | R3: =VLOOKUP('22'!O3,Malzemeler!C:D,2,0) -> 1211.04 | S3: =+R3*Q3 -> 1211.04
B4: 22 | C4: sabit | D4: sabit | E4: sabit | F4: sabit | G4: sabit | H4: sabit | I4: sabit | J4: =SUBTOTAL(103,B4) -> 1 | L4: MEKANİK | M4: 2 | N4: Copeland Karter Isıtıcı ID:8561105 | O4: R20KI08561105 | P4: Adet | Q4: 1 | R4: =VLOOKUP('22'!O4,Malzemeler!C:D,2,0) -> 40.7085 | S4: =+R4*Q4 -> 40.7085
B5: 22 | C5: sabit | D5: sabit | E5: sabit | F5: sabit | G5: sabit | H5: sabit | I5: sabit | J5: =SUBTOTAL(103,B5) -> 1 | L5: MEKANİK | M5: 3 | N5: Danfoss Drier DML305 5/8" 023Z0051 | O5: R20DML3055801 | P5: Adet | Q5: 1 | R5: =VLOOKUP('22'!O5,Malzemeler!C:D,2,0) -> 18.8 | S5: =+R5*Q5 -> 18.8
B6: 22 | C6: sabit | D6: sabit | E6: sabit | F6: sabit | G6: sabit | H6: sabit | I6: sabit | J6: =SUBTOTAL(103,B6) -> 1 | L6: MEKANİK | M6: 4 | N6: Danfoss Gözetleme Camı Kaynaklı SGP 16s N 5/8" 014L0145 | O6: R20SGP16SN580 | P6: Adet | Q6: 1 | R6: =VLOOKUP('22'!O6,Malzemeler!C:D,2,0) -> 14.5 | S6: =+R6*Q6 -> 14.5
B7: 22 | C7: sabit | D7: sabit | E7: sabit | F7: sabit | G7: sabit | H7: sabit | I7: sabit | J7: =SUBTOTAL(103,B7) -> 1 | L7: MEKANİK | M7: 5 | N7: Danfoss Küresel Vana GBC 16s 5/8" 009L7023 | O7: R20GBC1658723 | P7: Adet | Q7: 1 | R7: =VLOOKUP('22'!O7,Malzemeler!C:D,2,0) -> 19.5 | S7: =+R7*Q7 -> 19.5
B8: 22 | C8: sabit | D8: sabit | E8: sabit | F8: sabit | G8: sabit | H8: sabit | I8: sabit | J8: =SUBTOTAL(103,B8) -> 1 | L8: MEKANİK | M8: 6 | N8: GVN LİKİT TANKI VLR.A.33b.10.B4.C4 | O8: R20LTVLR33104 | P8: Adet | Q8: 1 | R8: =VLOOKUP('22'!O8,Malzemeler!C:D,2,0) -> 0 | S8: =+R8*Q8 -> 0
B9: 22 | C9: sabit | D9: sabit | E9: sabit | F9: sabit | G9: sabit | H9: sabit | I9: sabit | J9: =SUBTOTAL(103,B9) -> 1 | L9: MEKANİK | M9: 7 | N9: BAKIR BORU Q16 (5/8'')-1 mm | O9: R20BBQ1600000 | P9: Adet | Q9: 2 | R9: =VLOOKUP('22'!O9,Malzemeler!C:D,2,0) -> 7.85 | S9: =+R9*Q9 -> 15.7
B10: 22 | C10: sabit | D10: sabit | E10: sabit | F10: sabit | G10: sabit | H10: sabit | I10: sabit | J10: =SUBTOTAL(103,B10) -> 1 | L10: MEKANİK | M10: 8 | N10: BAKIR BORU Q28 (1 1/8")-1,5 MM | O10: R20BBQ2800000 | P10: Adet | Q10: 3 | R10: =VLOOKUP('22'!O10,Malzemeler!C:D,2,0) -> 20.8 | S10: =+R10*Q10 -> 62.4
B11: 22 | C11: sabit | D11: sabit | E11: sabit | F11: sabit | G11: sabit | H11: sabit | I11: sabit | J11: =SUBTOTAL(103,B11) -> 1 | L11: MEKANİK | M11: 9 | N11: BAKIR BORU Q22 (7/8'')-1,5 mm | O11: R20BBQ2200000 | P11: Adet | Q11: 2 | R11: =VLOOKUP('22'!O11,Malzemeler!C:D,2,0) -> 16.15 | S11: =+R11*Q11 -> 32.3
B12: 22 | C12: sabit | D12: sabit | E12: sabit | F12: sabit | G12: sabit | H12: sabit | I12: sabit | J12: =SUBTOTAL(103,B12) -> 1 | L12: MEKANİK | M12: 10 | N12: 5/8'' Bakır Dirsek | O12: R20BD58000000 | P12: Adet | Q12: 4 | R12: =VLOOKUP('22'!O12,Malzemeler!C:D,2,0) -> 0.3 | S12: =+R12*Q12 -> 1.2
B13: 22 | C13: sabit | D13: sabit | E13: sabit | F13: sabit | G13: sabit | H13: sabit | I13: sabit | J13: =SUBTOTAL(103,B13) -> 1 | L13: MEKANİK | M13: 11 | N13: 1 1/8 İzolasyon 9'luk | O13: R10IZ90280006 | P13: Metre | Q13: 2 | R13: =VLOOKUP('22'!O13,Malzemeler!C:D,2,0) -> 0.3 | S13: =+R13*Q13 -> 0.6
B14: 22 | C14: sabit | D14: sabit | E14: sabit | F14: sabit | G14: sabit | H14: sabit | I14: sabit | J14: =SUBTOTAL(103,B14) -> 1 | L14: MEKANİK | M14: 12 | N14: BAKIR REDÜKSİYON 16X12 | O14: R20BR16X12000 | P14: Adet | Q14: 0.1 | R14: =VLOOKUP('22'!O14,Malzemeler!C:D,2,0) -> 0.3 | S14: =+R14*Q14 -> 0.03
B15: 22 | C15: sabit | D15: sabit | E15: sabit | F15: sabit | G15: sabit | H15: sabit | I15: sabit | J15: =SUBTOTAL(103,B15) -> 1 | L15: MEKANİK | M15: 13 | N15: BAKIR REDÜKSİYON 28x22 | O15: R20BR28X22000 | P15: Adet | Q15: 2 | R15: =VLOOKUP('22'!O15,Malzemeler!C:D,2,0) -> 0.95 | S15: =+R15*Q15 -> 1.9
... B28: 22 | C28: L | D28: sabit | E28: sabit | F28: sabit | G28: sabit | H28: sabit | I28: sabit | J28: =SUBTOTAL(103,B28) -> 1 | L28: MEKANİK - SOL | M28: 23 | N28: ISITICI F 32x28-12 C S 26T 2R 1070A 3.2P 5NC | O28: - | P28: Adet | Q28: 1 | R28: =VLOOKUP('22'!O28,Malzemeler!C:D,2,0) -> 410 | S28: =+R28*Q28 -> 410
B29: 22 | C29: L | D29: sabit | E29: sabit | F29: sabit | G29: sabit | H29: sabit | I29: sabit | J29: =SUBTOTAL(103,B29) -> 1 | L29: MEKANİK - SOL | M29: 24 | N29: KONDENSER F 25x22-3/8 L G 32T 3R 1080A 2.5P 12NC | P29: Adet | Q29: 1 | R29: =VLOOKUP('22'!O29,Malzemeler!C:D,2,0) -> #N/A | S29: =+R29*Q29 -> #N/A
B30: 22 | C30: L | D30: sabit | E30: sabit | F30: sabit | G30: sabit | H30: sabit | I30: sabit | J30: =SUBTOTAL(103,B30) -> 1 | L30: MEKANİK - SOL | M30: 25 | N30: EVAPARATÖR F 32x28-12 C S 18T 6R 1065A 2P 6NC | P30: Adet | Q30: 1 | R30: =VLOOKUP('22'!O30,Malzemeler!C:D,2,0) -> #N/A | S30: =+R30*Q30 -> #N/A
B31: 22 | C31: sabit | D31: sabit | E31: sabit | F31: sabit | G31: sabit | H31: sabit | I31: sabit | J31: =SUBTOTAL(103,B31) -> 1 | L31: MEKANİK | M31: 26 | N31: CİVATA-BOLT 8x35 | O31: CİVATA-BOLT 8x35 | P31: Adet | Q31: 8 | R31: =VLOOKUP('22'!O31,Malzemeler!C:D,2,0) -> 0 | S31: =+R31*Q31 -> 0
B32: 22 | C32: sabit | D32: sabit | E32: sabit | F32: sabit | G32: sabit | H32: sabit | I32: sabit | J32: =SUBTOTAL(103,B32) -> 1 | L32: MEKANİK | M32: 27 | N32: CİVATA-BOLT M6x30 İnbus | O32: CİVATA-BOLT M6x30 İnbus | P32: Adet | Q32: 20 | R32: =VLOOKUP('22'!O32,Malzemeler!C:D,2,0) -> 0 | S32: =+R32*Q32 -> 0
B33: 22 | C33: sabit | D33: sabit | E33: sabit | F33: sabit | G33: sabit | H33: sabit | I33: sabit | J33: =SUBTOTAL(103,B33) -> 1 | L33: MEKANİK | M33: 28 | N33: CONTA-GASKET 3x25 | O33: CONTA-GASKET 3x25 | P33: Adet | Q33: 14 | R33: =VLOOKUP('22'!O33,Malzemeler!C:D,2,0) -> 0 | S33: =+R33*Q33 -> 0
B34: 22 | C34: sabit | D34: sabit | E34: sabit | F34: sabit | G34: sabit | H34: sabit | I34: sabit | J34: =SUBTOTAL(103,B34) -> 1 | L34: MEKANİK | M34: 29 | N34: PUL-WASHER M8 | O34: PUL-WASHER M8 | P34: Adet | Q34: 8 | R34: =VLOOKUP('22'!O34,Malzemeler!C:D,2,0) -> 0 | S34: =+R34*Q34 -> 0
B35: 22 | C35: sabit | D35: sabit | E35: sabit | F35: sabit | G35: sabit | H35: sabit | I35: sabit | J35: =SUBTOTAL(103,B35) -> 1 | L35: MEKANİK | M35: 30 | N35: 0,8 mm Z275 DX51 RAL7035 Boyalı Rulo Sac | O35: R01B080000001 | P35: Adet | Q35: 803.10992 | R35: =VLOOKUP('22'!O35,Malzemeler!C:D,2,0) -> 1.07 | S35: =+R35*Q35 -> 859.32761
B36: 22 | C36: sabit | D36: sabit | E36: sabit | F36: sabit | G36: sabit | H36: sabit | I36: sabit | J36: =SUBTOTAL(103,B36) -> 1 | L36: MEKANİK | M36: 31 | N36: 1.0 MM Z275 DX51 Rulo Sac | O36: R01GL10000275 | P36: Adet | Q36: 6.0112 | R36: =VLOOKUP('22'!O36,Malzemeler!C:D,2,0) -> 0 | S36: =+R36*Q36 -> 0
B37: 22 | C37: sabit | D37: sabit | E37: sabit | F37: sabit | G37: sabit | H37: sabit | I37: sabit | J37: =SUBTOTAL(103,B37) -> 1 | L37: MEKANİK | M37: 32 | N37: 0,8 MM 275 gr GALVANİZLİ SAC | O37: R01GL10000278 | P37: Adet | Q37: 10.0368 | R37: =VLOOKUP('22'!O37,Malzemeler!C:D,2,0) -> 1.23 | S37: =+R37*Q37 -> 12.345264
B38: 22 | C38: sabit | D38: sabit | E38: sabit | F38: sabit | G38: sabit | H38: sabit | I38: sabit | J38: =SUBTOTAL(103,B38) -> 1 | L38: MEKANİK | M38: 33 | N38: 2.00MM 275 gr GALVANIZLI SAC | O38: R01GL20000275 | P38: Adet | Q38: 87.398888 | R38: =VLOOKUP('22'!O38,Malzemeler!C:D,2,0) -> 0.8 | S38: =+R38*Q38 -> 69.91911
B39: 22 | C39: sabit | D39: sabit | E39: sabit | F39: sabit | G39: sabit | H39: sabit | I39: sabit | J39: =SUBTOTAL(103,B39) -> 1 | L39: MEKANİK | M39: 34 | N39: 3,0 MM 275 gr GALVANIZLI SAC | O39: R01GL30000275 | P39: Adet | Q39: 197.10072 | R39: =VLOOKUP('22'!O39,Malzemeler!C:D,2,0) -> 0.79 | S39: =+R39*Q39 -> 155.70957
B40: 22 | C40: sabit | D40: sabit | E40: sabit | F40: sabit | G40: sabit | H40: sabit | I40: sabit | J40: =SUBTOTAL(103,B40) -> 1 | L40: MEKANİK | M40: 35 | N40: 1,20MM 275 gr GALVANIZLI SAC | O40: R01GL36000275 | P40: Adet | Q40: 33.311043 | R40: =VLOOKUP('22'!O40,Malzemeler!C:D,2,0) -> 0.85 | S40: =+R40*Q40 -> 28.314386
B41: 22 | C41: sabit | D41: sabit | E41: sabit | F41: sabit | G41: sabit | H41: sabit | I41: sabit | J41: =SUBTOTAL(103,B41) -> 1 | L41: MEKANİK | M41: 36 | N41: 0,80 MM PASLANMAZ SAC | O41: R01PS08000000 | P41: Adet | Q41: 24.52545 | R41: =VLOOKUP('22'!O41,Malzemeler!C:D,2,0) -> 2.32 | S41: =+R41*Q41 -> 56.899044
B42: 22 | C42: sabit | D42: sabit | E42: sabit | F42: sabit | G42: sabit | H42: sabit | I42: sabit | J42: =SUBTOTAL(103,B42) -> 1 | L42: MEKANİK | M42: 37 | N42: 20X30 GALVANIZ KUTU PROFIL | O42: R02KP12300000 | P42: Adet | Q42: 5.3856 | R42: =VLOOKUP('22'!O42,Malzemeler!C:D,2,0) -> 0 | S42: =+R42*Q42 -> 0
... B93: 22 | C93: sabit | D93: sabit | E93: sabit | F93: sabit | G93: sabit | H93: sabit | I93: sabit | J93: =SUBTOTAL(103,B93) -> 1 | L93: MEKANİK | M93: 88 | N93: MONTAJ İŞÇİLİK OVERHEAD | O93: HIZM000000010 | P93: Adet | Q93: 83.93 | R93: =VLOOKUP('22'!O93,Malzemeler!C:D,2,0) -> 0 | S93: =+R93*Q93 -> 0
A94: OTOMASYON | B94: 22 | C94: sabit | D94: sabit | E94: sabit | F94: sabit | G94: sabit | H94: sabit | I94: sabit | J94: =SUBTOTAL(103,B94) -> 1 | L94: OTOMASYON | M94: 1 | N94: REFNOX Alçak Basınç Swtich WPS-03L059/1,7G2,7G | O94: R27ABS00R1737 | P94: Adet | Q94: 1 | R94: =VLOOKUP('22'!O94,Malzemeler!C:D,2,0) -> 4.76 | S94: =+R94*Q94 -> 4.76
B95: 22 | C95: sabit | D95: sabit | E95: sabit | F95: sabit | G95: sabit | H95: sabit | I95: sabit | J95: =SUBTOTAL(103,B95) -> 1 | L95: OTOMASYON | M95: 2 | N95: REFNOX Yüksek Basınç Swtich WPS-03H059/42R33R | O95: R27YBS00R4232 | P95: Adet | Q95: 1 | R95: =VLOOKUP('22'!O95,Malzemeler!C:D,2,0) -> 4.76 | S95: =+R95*Q95 -> 4.76
B96: 22 | C96: sabit | D96: sabit | E96: sabit | F96: sabit | G96: sabit | H96: sabit | I96: sabit | J96: =SUBTOTAL(103,B96) -> 1 | L96: OTOMASYON | M96: 3 | N96: CAREL E2V30FSFC0 ELECTRONIC EXPANSION VALVE E2V30-F 12-12 ODF W/O STATOR | O96: R27CRLE2V3012 | P96: Adet | Q96: 1 | R96: =VLOOKUP('22'!O96,Malzemeler!C:D,2,0) -> 0 | S96: =+R96*Q96 -> 0
B97: 22 | C97: sabit | D97: sabit | E97: sabit | F97: sabit | G97: sabit | H97: sabit | I97: sabit | J97: =SUBTOTAL(103,B97) -> 1 | L97: OTOMASYON | M97: 4 | N97: CAREL E2VSTA0201 BIPOLAR STATOR FOR E2VB | O97: R27E2V0220100 | P97: Adet | Q97: 1 | R97: =VLOOKUP('22'!O97,Malzemeler!C:D,2,0) -> 40.53 | S97: =+R97*Q97 -> 40.53
B98: 22 | C98: sabit | D98: sabit | E98: sabit | F98: sabit | G98: sabit | H98: sabit | I98: sabit | J98: =SUBTOTAL(103,B98) -> 1 | L98: OTOMASYON | M98: 5 | N98: CAREL SPKT00B6P0 PRESS.TRASD.0-5V | O98: R27CL02250001 | P98: Adet | Q98: 1 | R98: =VLOOKUP('22'!O98,Malzemeler!C:D,2,0) -> 46.47 | S98: =+R98*Q98 -> 46.47
B99: 22 | C99: sabit | D99: sabit | E99: sabit | F99: sabit | G99: sabit | H99: sabit | I99: sabit | J99: =SUBTOTAL(103,B99) -> 1 | L99: OTOMASYON | M99: 6 | N99: Alçak Basınç Trans 0-5Vdc 0-17.3bar SPKT0043P0 | O99: R20SPKT0043R0 | P99: Adet | Q99: 1 | R99: =VLOOKUP('22'!O99,Malzemeler!C:D,2,0) -> 74.48 | S99: =+R99*Q99 -> 74.48
B100: 22 | C100: sabit | D100: sabit | E100: sabit | F100: sabit | G100: sabit | H100: sabit | I100: sabit | J100: =SUBTOTAL(103,B100) -> 1 | L100: OTOMASYON | M100: 7 | N100: CAREL P+500B0A000M0 PCO5+ MEDIUM, FB/BMS NO OPTO, NO USB | O100: R27CP50000000 | P100: Adet | Q100: 1 | R100: =VLOOKUP('22'!O100,Malzemeler!C:D,2,0) -> 675.52 | S100: =+R100*Q100 -> 675.52
B101: 22 | C101: sabit | D101: sabit | E101: sabit | F101: sabit | G101: sabit | H101: sabit | I101: sabit | J101: =SUBTOTAL(103,B101) -> 1 | L101: OTOMASYON | M101: 8 | N101: CAREL CONNECTOR P+50CON0M0 | O101: R27C050000000 | P101: Adet | Q101: 1 | R101: =VLOOKUP('22'!O101,Malzemeler!C:D,2,0) -> 23.17 | S101: =+R101*Q101 -> 23.17
B102: 22 | C102: sabit | D102: sabit | E102: sabit | F102: sabit | G102: sabit | H102: sabit | I102: sabit | J102: =SUBTOTAL(103,B102) -> 1 | L102: OTOMASYON | M102: 9 | N102: Ekran pGD1 PGD1000FW0 | O102: R27PGD1000FW0 | P102: Adet | Q102: 1 | R102: =VLOOKUP('22'!O102,Malzemeler!C:D,2,0) -> 130.16 | S102: =+R102*Q102 -> 130.16
...

Sheet 32
B1: Model | C1: Yön | D1: Besleme Filtre | E1: Dönüş Filtre | F1: Soğutucu Batarya | G1: Dış Ortam | H1: Ön Isıtıcı | I1: TCP/IP | N1: HPL 32 | W1: M5/F9 FİLTRE
B2: 32 | C2: sabit | D2: sabit | E2: sabit | F2: sabit | G2: sabit | H2: sabit | I2: sabit | J2: =SUBTOTAL(103,B2) -> 1 | M2: No | N2: MALZEME ADI | O2: ERP KODU | P2: BİRİM | Q2: MİKTAR | R2: BİRİM FİYAT | S2: TOPLAM FİYAT
A3: MEKANİK | B3: 32 | C3: sabit | D3: sabit | E3: sabit | F3: sabit | G3: sabit | H3: sabit | I3: sabit | J3: =SUBTOTAL(103,B3) -> 1 | L3: MEKANİK | M3: 1 | N3: Kompresör ZP122KCE-TFD 7/8x11/8 | O3: R20KMZP122003 | P3: Adet | Q3: 1 | R3: =VLOOKUP('32'!O3,Malzemeler!C:D,2,0) -> 1444.06 | S3: =+R3*Q3 -> 1444.06
B4: 32 | C4: sabit | D4: sabit | E4: sabit | F4: sabit | G4: sabit | H4: sabit | I4: sabit | J4: =SUBTOTAL(103,B4) -> 1 | L4: MEKANİK | M4: 2 | N4: Copeland Karter Isıtıcı ID:8561105 | O4: R20KI08561105 | P4: Adet | Q4: 1 | R4: =VLOOKUP('32'!O4,Malzemeler!C:D,2,0) -> 40.7085 | S4: =+R4*Q4 -> 40.7085
B5: 32 | C5: sabit | D5: sabit | E5: sabit | F5: sabit | G5: sabit | H5: sabit | I5: sabit | J5: =SUBTOTAL(103,B5) -> 1 | L5: MEKANİK | M5: 3 | N5: Danfoss Drier DML305 5/8" 023Z0051 | O5: R20DML3055801 | P5: Adet | Q5: 1 | R5: =VLOOKUP('32'!O5,Malzemeler!C:D,2,0) -> 18.8 | S5: =+R5*Q5 -> 18.8
B6: 32 | C6: sabit | D6: sabit | E6: sabit | F6: sabit | G6: sabit | H6: sabit | I6: sabit | J6: =SUBTOTAL(103,B6) -> 1 | L6: MEKANİK | M6: 4 | N6: Danfoss Gözetleme Camı Kaynaklı SGP 16s N 5/8" 014L0145 | O6: R20SGP16SN580 | P6: Adet | Q6: 1 | R6: =VLOOKUP('32'!O6,Malzemeler!C:D,2,0) -> 14.5 | S6: =+R6*Q6 -> 14.5
B7: 32 | C7: sabit | D7: sabit | E7: sabit | F7: sabit | G7: sabit | H7: sabit | I7: sabit | J7: =SUBTOTAL(103,B7) -> 1 | L7: MEKANİK | M7: 5 | N7: Danfoss Küresel Vana GBC 16s 5/8" 009L7023 | O7: R20GBC1658723 | P7: Adet | Q7: 1 | R7: =VLOOKUP('32'!O7,Malzemeler!C:D,2,0) -> 19.5 | S7: =+R7*Q7 -> 19.5
B8: 32 | C8: sabit | D8: sabit | E8: sabit | F8: sabit | G8: sabit | H8: sabit | I8: sabit | J8: =SUBTOTAL(103,B8) -> 1 | L8: MEKANİK | M8: 6 | N8: GVN LİKİT TANKI VLR.A.30b.12.B4.C4.F4 | O8: R20LTVLR30124 | P8: Adet | Q8: 1 | R8: =VLOOKUP('32'!O8,Malzemeler!C:D,2,0) -> 0 | S8: =+R8*Q8 -> 0
B9: 32 | C9: sabit | D9: sabit | E9: sabit | F9: sabit | G9: sabit | H9: sabit | I9: sabit | J9: =SUBTOTAL(103,B9) -> 1 | L9: MEKANİK | M9: 7 | N9: BAKIR BORU Q16 (5/8'')-1 mm | O9: R20BBQ1600000 | P9: Adet | Q9: 2.1 | R9: =VLOOKUP('32'!O9,Malzemeler!C:D,2,0) -> 7.85 | S9: =+R9*Q9 -> 16.485
B10: 32 | C10: sabit | D10: sabit | E10: sabit | F10: sabit | G10: sabit | H10: sabit | I10: sabit | J10: =SUBTOTAL(103,B10) -> 1 | L10: MEKANİK | M10: 8 | N10: BAKIR BORU Q22 (7/8'')-1,5 mm | O10: R20BBQ2200000 | P10: Adet | Q10: 3.2 | R10: =VLOOKUP('32'!O10,Malzemeler!C:D,2,0) -> 16.15 | S10: =+R10*Q10 -> 51.68
B11: 32 | C11: sabit | D11: sabit | E11: sabit | F11: sabit | G11: sabit | H11: sabit | I11: sabit | J11: =SUBTOTAL(103,B11) -> 1 | L11: MEKANİK | M11: 9 | N11: BAKIR BORU Q28 (1 1/8'')-1,5 mm | O11: R20BBQ2800000 | P11: Adet | Q11: 2.2 | R11: =VLOOKUP('32'!O11,Malzemeler!C:D,2,0) -> 20.8 | S11: =+R11*Q11 -> 45.76
B12: 32 | C12: sabit | D12: sabit | E12: sabit | F12: sabit | G12: sabit | H12: sabit | I12: sabit | J12: =SUBTOTAL(103,B12) -> 1 | L12: MEKANİK | M12: 10 | N12: 5/8'' Bakır Dirsek | O12: R20BD58000000 | P12: Adet | Q12: 4 | R12: =VLOOKUP('32'!O12,Malzemeler!C:D,2,0) -> 0.3 | S12: =+R12*Q12 -> 1.2
B13: 32 | C13: sabit | D13: sabit | E13: sabit | F13: sabit | G13: sabit | H13: sabit | I13: sabit | J13: =SUBTOTAL(103,B13) -> 1 | L13: MEKANİK | M13: 11 | N13: 1 1/8 İzolasyon 9'luk | O13: R10IZ90280006 | P13: Metre | Q13: 2 | R13: =VLOOKUP('32'!O13,Malzemeler!C:D,2,0) -> 0.3 | S13: =+R13*Q13 -> 0.6
B14: 32 | C14: sabit | D14: sabit | E14: sabit | F14: sabit | G14: sabit | H14: sabit | I14: sabit | J14: =SUBTOTAL(103,B14) -> 1 | L14: MEKANİK | M14: 12 | N14: Gümüş KAYNAK TELİ | O14: R20GK30000000 | P14: Adet | Q14: 0.3 | R14: =VLOOKUP('32'!O14,Malzemeler!C:D,2,0) -> 1615.6 | S14: =+R14*Q14 -> 484.68
B15: 32 | C15: sabit | D15: sabit | E15: sabit | F15: sabit | G15: sabit | H15: sabit | I15: sabit | J15: =SUBTOTAL(103,B15) -> 1 | L15: MEKANİK | M15: 13 | N15: BAKIR KAYNAK TELİ | O15: R20BAKIRKT001 | P15: Adet | Q15: 0.4 | R15: =VLOOKUP('32'!O15,Malzemeler!C:D,2,0) -> 40 | S15: =+R15*Q15 -> 16
... B91: 32 | C91: sabit | D91: sabit | E91: sabit | F91: sabit | G91: sabit | H91: sabit | I91: sabit | J91: =SUBTOTAL(103,B91) -> 1 | L91: MEKANİK | M91: 86 | N91: MONTAJ İŞÇİLİK OVERHEAD | O91: HIZM000000010 | P91: Adet | Q91: 89.11 | R91: =VLOOKUP('32'!O91,Malzemeler!C:D,2,0) -> 0 | S91: =+R91*Q91 -> 0
A92: OTOMASYON | B92: 32 | C92: sabit | D92: sabit | E92: sabit | F92: sabit | G92: sabit | H92: sabit | I92: sabit | J92: =SUBTOTAL(103,B92) -> 1 | L92: OTOMASYON | M92: 1 | N92: REFNOX Alçak Basınç Swtich WPS-03L059/1,7G2,7G | O92: R27ABS00R1737 | P92: Adet | Q92: 1 | R92: =VLOOKUP('32'!O92,Malzemeler!C:D,2,0) -> 4.76 | S92: =+R92*Q92 -> 4.76
B93: 32 | C93: sabit | D93: sabit | E93: sabit | F93: sabit | G93: sabit | H93: sabit | I93: sabit | J93: =SUBTOTAL(103,B93) -> 1 | L93: OTOMASYON | M93: 2 | N93: REFNOX Yüksek Basınç Swtich WPS-03H059/42R33R | O93: R27YBS00R4232 | P93: Adet | Q93: 1 | R93: =VLOOKUP('32'!O93,Malzemeler!C:D,2,0) -> 4.76 | S93: =+R93*Q93 -> 4.76
B94: 32 | C94: sabit | D94: sabit | E94: sabit | F94: sabit | G94: sabit | H94: sabit | I94: sabit | J94: =SUBTOTAL(103,B94) -> 1 | L94: OTOMASYON | M94: 3 | N94: CAREL E2V30FSFC0 ELECTRONIC EXPANSION VALVE E2V30-F 12-12 ODF W/O STATOR | O94: R27CRLE2V3012 | P94: Adet | Q94: 1 | R94: =VLOOKUP('32'!O94,Malzemeler!C:D,2,0) -> 0 | S94: =+R94*Q94 -> 0
B95: 32 | C95: sabit | D95: sabit | E95: sabit | F95: sabit | G95: sabit | H95: sabit | I95: sabit | J95: =SUBTOTAL(103,B95) -> 1 | L95: OTOMASYON | M95: 4 | N95: CAREL E2VSTA0201 BIPOLAR STATOR FOR E2VB | O95: R27E2V0220100 | P95: Adet | Q95: 1 | R95: =VLOOKUP('32'!O95,Malzemeler!C:D,2,0) -> 40.53 | S95: =+R95*Q95 -> 40.53
B96: 32 | C96: sabit | D96: sabit | E96: sabit | F96: sabit | G96: sabit | H96: sabit | I96: sabit | J96: =SUBTOTAL(103,B96) -> 1 | L96: OTOMASYON | M96: 5 | N96: CAREL SPKT00B6P0 PRESS.TRASD.0-5V | O96: R27CL02250001 | P96: Adet | Q96: 1 | R96: =VLOOKUP('32'!O96,Malzemeler!C:D,2,0) -> 46.47 | S96: =+R96*Q96 -> 46.47
B97: 32 | C97: sabit | D97: sabit | E97: sabit | F97: sabit | G97: sabit | H97: sabit | I97: sabit | J97: =SUBTOTAL(103,B97) -> 1 | L97: OTOMASYON | M97: 6 | N97: Alçak Basınç Trans 0-5Vdc 0-17.3bar SPKT0043P0 | O97: R20SPKT0043R0 | P97: Adet | Q97: 1 | R97: =VLOOKUP('32'!O97,Malzemeler!C:D,2,0) -> 74.48 | S97: =+R97*Q97 -> 74.48
B98: 32 | C98: sabit | D98: sabit | E98: sabit | F98: sabit | G98: sabit | H98: sabit | I98: sabit | J98: =SUBTOTAL(103,B98) -> 1 | L98: OTOMASYON | M98: 7 | N98: CAREL P+500B0A000M0 PCO5+ MEDIUM, FB/BMS NO OPTO, NO USB | O98: R27CP50000000 | P98: Adet | Q98: 1 | R98: =VLOOKUP('32'!O98,Malzemeler!C:D,2,0) -> 675.52 | S98: =+R98*Q98 -> 675.52
B99: 32 | C99: sabit | D99: sabit | E99: sabit | F99: sabit | G99: sabit | H99: sabit | I99: sabit | J99: =SUBTOTAL(103,B99) -> 1 | L99: OTOMASYON | M99: 8 | N99: CAREL CONNECTOR P+50CON0M0 | O99: R27C050000000 | P99: Adet | Q99: 1 | R99: =VLOOKUP('32'!O99,Malzemeler!C:D,2,0) -> 23.17 | S99: =+R99*Q99 -> 23.17
B100: 32 | C100: sabit | D100: sabit | E100: sabit | F100: sabit | G100: sabit | H100: sabit | I100: sabit | J100: =SUBTOTAL(103,B100) -> 1 | L100: OTOMASYON | M100: 9 | N100: Ekran pGD1 PGD1000FW0 | O100: R27PGD1000FW0 | P100: Adet | Q100: 1 | R100: =VLOOKUP('32'!O100,Malzemeler!C:D,2,0) -> 130.16 | S100: =+R100*Q100 -> 130.16
B101: 32 | C101: sabit | D101: sabit | E101: sabit | F101: sabit | G101: sabit | H101: sabit | I101: sabit | J101: =SUBTOTAL(103,B101) -> 1 | L101: OTOMASYON | M101: 10 | N101: KabloS90CONN000 | O101: R27S90CONN000 | P101: Adet | Q101: 1 | R101: =VLOOKUP('32'!O101,Malzemeler!C:D,2,0) -> 130.16 | S101: =+R101*Q101 -> 130.16
B102: 32 | C102: sabit | D102: sabit | E102: sabit | F102: sabit | G102: sabit | H102: sabit | I102: sabit | J102: =SUBTOTAL(103,B102) -> 1 | L102: OTOMASYON | M102: 11 | N102: SPKC005310 (5MT) | O102: R27SPKC531000 | P102: Adet | Q102: 2 | R102: =VLOOKUP('32'!O102,Malzemeler!C:D,2,0) -> 4.73 | S102: =+R102*Q102 -> 9.46
B103: 32 | C103: sabit | D103: sabit | E103: sabit | F103: sabit | G103: sabit | H103: sabit | I103: sabit | J103: =SUBTOTAL(103,B103) -> 1 | L103: OTOMASYON | M103: 12 | N103: CAREL DPDC111000 DUCTSENSOR TEMP.-10T60GR.C. | O103: R27DP00200309 | P103: Adet | Q103: 2 | R103: =VLOOKUP('32'!O103,Malzemeler!C:D,2,0) -> 155.05 | S103: =+R103*Q103 -> 310.1
B104: 32 | C104: sabit | D104: sabit | E104: sabit | F104: sabit | G104: sabit | H104: sabit | I104: sabit | J104: =SUBTOTAL(103,B104) -> 1 | L104: OTOMASYON | M104: 13 | N104: CAREL EVD0000E41 EVD EVOLUTION FOR CAREL VALVES (PLAN) MULTIPLE PACKAGE (10) | O104: R27EVD0000041 | P104: Adet | Q104: 1 | R104: =VLOOKUP('32'!O104,Malzemeler!C:D,2,0) -> 238.61 | S104: =+R104*Q104 -> 238.61
... B124: 32 | C124: sabit | D124: sabit | E124: sabit | F124: sabit | G124: sabit | H124: sabit | I124: sabit | J124: =SUBTOTAL(103,B124) -> 1 | L124: OTOMASYON | M124: 34 | N124: LIHCH KABLO 2X0,75 | O124: R12KBLIHCH2X0 | P124: Metre | Q124: 35 | R124: =VLOOKUP('32'!O124,Malzemeler!C:D,2,0) -> 0 | S124: =+R124*Q124 -> 0
A125: FİLTRE | B125: 32 | C125: sabit | D125: 47 | E125: 5 | F125: sabit | G125: sabit | H125: sabit | I125: sabit | J125: =SUBTOTAL(103,B125) -> 1 | L125: FİLTRE | M125: 1 | N125: PANEL FİLTRE M5 - 592-592-48 | O125: R17PM54610610 | P125: Adet | Q125: 2 | R125: =VLOOKUP('32'!O125,Malzemeler!C:D,2,0) -> 4.43 | S125: =+R125*Q125 -> 8.86
B126: 32 | C126: sabit | D126: 47 | E126: 5 | F126: sabit | G126: sabit | H126: sabit | I126: sabit | J126: =SUBTOTAL(103,B126) -> 1 | L126: FİLTRE | M126: 2 | N126: PANEL FİLTRE M5 - 287-592-48 | O126: R17PM54305610 | P126: Adet | Q126: 3 | R126: =VLOOKUP('32'!O126,Malzemeler!C:D,2,0) -> 3.04 | S126: =+R126*Q126 -> 9.12
B127: 32 | C127: sabit | D127: 47 | E127: 5 | F127: sabit | G127: sabit | H127: sabit | I127: sabit | J127: =SUBTOTAL(103,B127) -> 1 | L127: FİLTRE | M127: 3 | N127: PANEL FİLTRE M5 - 287-287-48 | O127: R17PM54305305 | P127: Adet | Q127: 1 | R127: =VLOOKUP('32'!O127,Malzemeler!C:D,2,0) -> 2 | S127: =+R127*Q127 -> 2
B128: 32 | C128: sabit | D128: 47 | E128: 5 | F128: sabit | G128: sabit | H128: sabit | I128: sabit | J128: =SUBTOTAL(103,B128) -> 1 | L128: FİLTRE | M128: 4 | N128: PANEL FİLTRE G4 - 592-592-48 | O128: R17G4P5959048 | P128: Adet | Q128: 2 | R128: =VLOOKUP('32'!O128,Malzemeler!C:D,2,0) -> 4.55 | S128: =+R128*Q128 -> 9.1
B129: 32 | C129: sabit | D129: 47 | E129: 5 | F129: sabit | G129: sabit | H129: sabit | I129: sabit | J129: =SUBTOTAL(103,B129) -> 1 | L129: FİLTRE | M129: 5 | N129: PANEL FİLTRE G4 - 287-592-48 | O129: R17G4P2859048 | P129: Adet | Q129: 3 | R129: =VLOOKUP('32'!O129,Malzemeler!C:D,2,0) -> 2.96 | S129: =+R129*Q129 -> 8.88
B130: 32 | C130: sabit | D130: 47 | E130: 5 | F130: sabit | G130: sabit | H130: sabit | I130: sabit | J130: =SUBTOTAL(103,B130) -> 1 | L130: FİLTRE | M130: 6 | N130: PANEL FİLTRE G4 - 287-287-48 | O130: R17G4P2828048 | P130: Adet | Q130: 1 | R130: =VLOOKUP('32'!O130,Malzemeler!C:D,2,0) -> 2 | S130: =+R130*Q130 -> 2
B131: 32 | C131: sabit | D131: 47 | E131: 5 | F131: sabit | G131: sabit | H131: sabit | I131: sabit | J131: =SUBTOTAL(103,B131) -> 1 | L131: FİLTRE | M131: 7 | N131: F7 TORBA FİLTRE 592X592X300 GENERAL | O131: R17F75530000G | P131: Adet | Q131: 2 | R131: =VLOOKUP('32'!O131,Malzemeler!C:D,2,0) -> 7.15 | S131: =+R131*Q131 -> 14.3
B132: 32 | C132: sabit | D132: 47 | E132: 5 | F132: sabit | G132: sabit | H132: sabit | I132: sabit | J132: =SUBTOTAL(103,B132) -> 1 | L132: FİLTRE | M132: 8 | N132: F7 TORBA FİLTRE 287X592X300 GENERAL | O132: R17F72530000G | P132: Adet | Q132: 3 | R132: =VLOOKUP('32'!O132,Malzemeler!C:D,2,0) -> 4.37 | S132: =+R132*Q132 -> 13.11
B133: 32 | C133: sabit | D133: 47 | E133: 5 | F133: sabit | G133: sabit | H133: sabit | I133: sabit | J133: =SUBTOTAL(103,B133) -> 1 | L133: FİLTRE | M133: 9 | N133: F7 TORBA FİLTRE 287X287X300 GENERAL | O133: R17F72230000G | P133: Adet | Q133: 1 | R133: =VLOOKUP('32'!O133,Malzemeler!C:D,2,0) -> 3.3 | S133: =+R133*Q133 -> 3.3
B134: 32 | C134: sabit | D134: 5 | E134: 5 | F134: sabit | G134: sabit | H134: sabit | I134: sabit | J134: =SUBTOTAL(103,B134) -> 1 | L134: FİLTRE | M134: 1 | N134: PANEL FİLTRE M5 - 592-592-48 | O134: R17PM54610610 | P134: Adet | Q134: 4 | R134: =VLOOKUP('32'!O134,Malzemeler!C:D,2,0) -> 4.43 | S134: =+R134*Q134 -> 17.72
...

Sheet 42
B1: Model | C1: Yön | D1: Besleme Filtre | E1: Dönüş Filtre | F1: Soğutucu Batarya | G1: Dış Ortam | H1: Ön Isıtıcı | I1: TCP/IP | N1: HPL42
B2: 42 | C2: sabit | D2: sabit | E2: sabit | F2: sabit | G2: sabit | H2: sabit | I2: sabit | J2: =SUBTOTAL(103,B2) -> 1 | M2: No | N2: MALZEME ADI | O2: ERP KODU | P2: BİRİM | Q2: MİKTAR | R2: BİRİM FİYAT | S2: TOPLAM FİYAT
A3: MEKANİK | B3: 42 | C3: sabit | D3: sabit | E3: sabit | F3: sabit | G3: sabit | H3: sabit | I3: sabit | J3: =SUBTOTAL(103,B3) -> 1 | L3: MEKANİK | M3: 1 | N3: Kompresör ZP182KCE-TFD 7/8x13/8 | O3: R20KMZP182004 | P3: Adet | Q3: 1 | R3: =VLOOKUP('42'!O3,Malzemeler!C:D,2,0) -> 1526.45 | S3: =+R3*Q3 -> 1526.45
B4: 42 | C4: sabit | D4: sabit | E4: sabit | F4: sabit | G4: sabit | H4: sabit | I4: sabit | J4: =SUBTOTAL(103,B4) -> 1 | L4: MEKANİK | M4: 2 | N4: Copeland Karter Isıtıcı ID:8622731 | O4: R20KI86227331 | P4: Adet | Q4: 1 | R4: =VLOOKUP('42'!O4,Malzemeler!C:D,2,0) -> 45.9165 | S4: =+R4*Q4 -> 45.9165
B5: 42 | C5: sabit | D5: sabit | E5: sabit | F5: sabit | G5: sabit | H5: sabit | I5: sabit | J5: =SUBTOTAL(103,B5) -> 1 | L5: MEKANİK | M5: 3 | N5: Danfoss Drier DML306 3/4" 023Z0193 | O5: R20DML3063401 | P5: Adet | Q5: 1 | R5: =VLOOKUP('42'!O5,Malzemeler!C:D,2,0) -> 18.8 | S5: =+R5*Q5 -> 18.8
B6: 42 | C6: sabit | D6: sabit | E6: sabit | F6: sabit | G6: sabit | H6: sabit | I6: sabit | J6: =SUBTOTAL(103,B6) -> 1 | L6: MEKANİK | M6: 4 | N6: Danfoss Gözetleme Camı Kaynaklı SGP 19s N 3/4" 014L0185 | O6: R20SGP19SN340 | P6: Adet | Q6: 1 | R6: =VLOOKUP('42'!O6,Malzemeler!C:D,2,0) -> 25.5 | S6: =+R6*Q6 -> 25.5
B7: 42 | C7: sabit | D7: sabit | E7: sabit | F7: sabit | G7: sabit | H7: sabit | I7: sabit | J7: =SUBTOTAL(103,B7) -> 1 | L7: MEKANİK | M7: 5 | N7: Danfoss Küresel Vana GBC 22s 7/8" 009L7025 | O7: R20GBC2278725 | P7: Adet | Q7: 1 | R7: =VLOOKUP('42'!O7,Malzemeler!C:D,2,0) -> 26.2 | S7: =+R7*Q7 -> 26.2
B8: 42 | C8: sabit | D8: sabit | E8: sabit | F8: sabit | G8: sabit | H8: sabit | I8: sabit | J8: =SUBTOTAL(103,B8) -> 1 | L8: MEKANİK | M8: 6 | N8: GVN LİKİT TANKI VLR.A.30b.16.B4.C4.F4 | O8: R20LTVLR30164 | P8: Adet | Q8: 1 | R8: =VLOOKUP('42'!O8,Malzemeler!C:D,2,0) -> 0 | S8: =+R8*Q8 -> 0
B9: 42 | C9: sabit | D9: sabit | E9: sabit | F9: sabit | G9: sabit | H9: sabit | I9: sabit | J9: =SUBTOTAL(103,B9) -> 1 | L9: MEKANİK | M9: 7 | N9: BAKIR Q19 Boru (3/4") -1 mm | O9: R20BBQ1900000 | P9: Adet | Q9: 3 | R9: =VLOOKUP('42'!O9,Malzemeler!C:D,2,0) -> 9.65 | S9: =+R9*Q9 -> 28.95
B10: 42 | C10: sabit | D10: sabit | E10: sabit | F10: sabit | G10: sabit | H10: sabit | I10: sabit | J10: =SUBTOTAL(103,B10) -> 1 | L10: MEKANİK | M10: 8 | N10: BAKIR BORU Q22 (7/8'')-1,5 mm | O10: R20BBQ2200000 | P10: Adet | Q10: 3 | R10: =VLOOKUP('42'!O10,Malzemeler!C:D,2,0) -> 16.15 | S10: =+R10*Q10 -> 48.45
B11: 42 | C11: sabit | D11: sabit | E11: sabit | F11: sabit | G11: sabit | H11: sabit | I11: sabit | J11: =SUBTOTAL(103,B11) -> 1 | L11: MEKANİK | M11: 9 | N11: BAKIR BORU Q35 (1 3/8")-1,5 MM | O11: R20BBQ3500000 | P11: Adet | Q11: 3 | R11: =VLOOKUP('42'!O11,Malzemeler!C:D,2,0) -> 26.5 | S11: =+R11*Q11 -> 79.5
B12: 42 | C12: sabit | D12: sabit | E12: sabit | F12: sabit | G12: sabit | H12: sabit | I12: sabit | J12: =SUBTOTAL(103,B12) -> 1 | L12: MEKANİK | M12: 10 | N12: 5/8'' Bakır Dirsek | O12: R20BD58000000 | P12: Adet | Q12: 4 | R12: =VLOOKUP('42'!O12,Malzemeler!C:D,2,0) -> 0.3 | S12: =+R12*Q12 -> 1.2
B13: 42 | C13: sabit | D13: sabit | E13: sabit | F13: sabit | G13: sabit | H13: sabit | I13: sabit | J13: =SUBTOTAL(103,B13) -> 1 | L13: MEKANİK | M13: 11 | N13: BAKIR REDÜKSİYON 28X16 | O13: R20BR28X16000 | P13: Adet | Q13: 2 | R13: =VLOOKUP('42'!O13,Malzemeler!C:D,2,0) -> 0.6 | S13: =+R13*Q13 -> 1.2
B14: 42 | C14: sabit | D14: sabit | E14: sabit | F14: sabit | G14: sabit | H14: sabit | I14: sabit | J14: =SUBTOTAL(103,B14) -> 1 | L14: MEKANİK | M14: 12 | N14: BAKIR REDÜKSİYON 35X28 | O14: R20BR35X28000 | P14: Adet | Q14: 1 | R14: =VLOOKUP('42'!O14,Malzemeler!C:D,2,0) -> 1.65 | S14: =+R14*Q14 -> 1.65
B15: 42 | C15: sabit | D15: sabit | E15: sabit | F15: sabit | G15: sabit | H15: sabit | I15: sabit | J15: =SUBTOTAL(103,B15) -> 1 | L15: MEKANİK | M15: 13 | N15: 1 3/8 Izolasyon 9luk | O15: R10IZ90280007 | P15: Metre | Q15: 5 | R15: =VLOOKUP('42'!O15,Malzemeler!C:D,2,0) -> 0 | S15: =+R15*Q15 -> 0
... B92: 42 | C92: sabit | D92: sabit | E92: sabit | F92: sabit | G92: sabit | H92: sabit | I92: sabit | J92: =SUBTOTAL(103,B92) -> 1 | L92: MEKANİK | M92: 87 | N92: MONTAJ İŞÇİLİK OVERHEAD | O92: HIZM000000010 | P92: Adet | Q92: 89.11 | R92: =VLOOKUP('42'!O92,Malzemeler!C:D,2,0) -> 0 | S92: =+R92*Q92 -> 0
